09-Jun-23 17:48:26 - root - ERROR - Exception occurred
Traceback (most recent call last):
  File "/Users/kaistudio/Desktop/Lotto-generate-website/server/main.py", line 33, in <module>
    with open('./lotto_data.xls', 'r', encoding='EUC-KR') as file:
         ^^^^^^^^^^^^^^^^^^^^^^^^^^^^^^^^^^^^^^^^^^^^^^^^
FileNotFoundError: [Errno 2] No such file or directory: './lotto_data.xls'
