08-Jun-23 10:36:44 - root - ERROR - Exception occurred
Traceback (most recent call last):
  File "/Users/kaistudio/Desktop/Lotto-generate-website/server/main.py", line 61, in <module>
    x_input = x_input.reshape((1, n_steps, 7))
              ^^^^^^^^^^^^^^^^^^^^^^^^^^^^^^^^
ValueError: cannot reshape array of size 7 into shape (1,5,7)
08-Jun-23 10:37:11 - root - ERROR - Exception occurred
Traceback (most recent call last):
  File "/Users/kaistudio/Desktop/Lotto-generate-website/server/main.py", line 61, in <module>
    x_input = x_input.reshape((1, n_steps, 7))
              ^^^^^^^^^^^^^^^^^^^^^^^^^^^^^^^^
ValueError: cannot reshape array of size 7 into shape (1,5,7)
08-Jun-23 10:38:40 - root - ERROR - Exception occurred
Traceback (most recent call last):
  File "/Users/kaistudio/Desktop/Lotto-generate-website/server/main.py", line 49, in <module>
    data = data.reverse()
           ^^^^^^^^^^^^
AttributeError: 'numpy.ndarray' object has no attribute 'reverse'
08-Jun-23 10:40:59 - root - ERROR - Exception occurred
Traceback (most recent call last):
  File "/Users/kaistudio/Desktop/Lotto-generate-website/server/main.py", line 62, in <module>
    x_input = x_input.reshape((1, n_steps, 7))
              ^^^^^^^^^^^^^^^^^^^^^^^^^^^^^^^^
ValueError: cannot reshape array of size 7 into shape (1,5,7)
08-Jun-23 10:45:02 - root - ERROR - Exception occurred
Traceback (most recent call last):
  File "/Users/kaistudio/Desktop/Lotto-generate-website/server/main.py", line 62, in <module>
    x_input = x_input.reshape((1, n_steps, 7))
              ^^^^^^^^^^^^^^^^^^^^^^^^^^^^^^^^
ValueError: cannot reshape array of size 7 into shape (1,5,7)
08-Jun-23 10:45:15 - root - ERROR - Exception occurred
Traceback (most recent call last):
  File "/Users/kaistudio/Desktop/Lotto-generate-website/server/main.py", line 62, in <module>
    x_input = x_input.reshape((1, n_steps, 7))
              ^^^^^^^^^^^^^^^^^^^^^^^^^^^^^^^^
ValueError: cannot reshape array of size 7 into shape (1,5,7)
08-Jun-23 10:45:55 - root - ERROR - Exception occurred
Traceback (most recent call last):
  File "/Users/kaistudio/Desktop/Lotto-generate-website/server/main.py", line 62, in <module>
    x_input = x_input.reshape((1, n_steps, 7))
              ^^^^^^^^^^^^^^^^^^^^^^^^^^^^^^^^
ValueError: cannot reshape array of size 1498 into shape (1,5,7)
08-Jun-23 10:49:07 - root - ERROR - Exception occurred
Traceback (most recent call last):
  File "/Users/kaistudio/Desktop/Lotto-generate-website/server/main.py", line 62, in <module>
    x_input = x_input.reshape((1, n_steps, 7))
              ^^^^^^^^^^^^^^^^^^^^^^^^^^^^^^^^
ValueError: cannot reshape array of size 0 into shape (1,5,7)
08-Jun-23 10:49:14 - root - ERROR - Exception occurred
Traceback (most recent call last):
  File "/Users/kaistudio/Desktop/Lotto-generate-website/server/main.py", line 62, in <module>
    x_input = x_input.reshape((1, n_steps, 7))
              ^^^^^^^^^^^^^^^^^^^^^^^^^^^^^^^^
ValueError: cannot reshape array of size 7 into shape (1,5,7)
08-Jun-23 10:50:09 - root - ERROR - Exception occurred
Traceback (most recent call last):
  File "/Users/kaistudio/Desktop/Lotto-generate-website/server/main.py", line 62, in <module>
    x_input = x_input.reshape((1, n_steps, 7))
              ^^^^^^^^^^^^^^^^^^^^^^^^^^^^^^^^
ValueError: cannot reshape array of size 14 into shape (1,5,7)
08-Jun-23 10:57:24 - root - ERROR - Exception occurred
Traceback (most recent call last):
  File "/Users/kaistudio/Desktop/Lotto-generate-website/server/main.py", line 62, in <module>
    x_input = x_input.reshape((1, 5, 7))
              ^^^^^^^^^^^^^^^^^^^^^^^^^^
ValueError: cannot reshape array of size 42 into shape (1,5,7)
08-Jun-23 10:57:34 - root - ERROR - Exception occurred
Traceback (most recent call last):
  File "/Users/kaistudio/Desktop/Lotto-generate-website/server/main.py", line 62, in <module>
    x_input = x_input.reshape((1, 5, 7))
              ^^^^^^^^^^^^^^^^^^^^^^^^^^
ValueError: cannot reshape array of size 42 into shape (1,5,7)
08-Jun-23 10:59:45 - root - ERROR - Exception occurred
Traceback (most recent call last):
  File "/Users/kaistudio/Desktop/Lotto-generate-website/server/main.py", line 65, in <module>
    rounded_predictions = np.argmax(predictions, axis=2)
                          ^^^^^^^^^^^^^^^^^^^^^^^^^^^^^^
  File "<__array_function__ internals>", line 200, in argmax
  File "/Users/kaistudio/.local/share/virtualenvs/server-vWPLkNok/lib/python3.11/site-packages/numpy/core/fromnumeric.py", line 1242, in argmax
    return _wrapfunc(a, 'argmax', axis=axis, out=out, **kwds)
           ^^^^^^^^^^^^^^^^^^^^^^^^^^^^^^^^^^^^^^^^^^^^^^^^^^
  File "/Users/kaistudio/.local/share/virtualenvs/server-vWPLkNok/lib/python3.11/site-packages/numpy/core/fromnumeric.py", line 57, in _wrapfunc
    return bound(*args, **kwds)
           ^^^^^^^^^^^^^^^^^^^^
numpy.AxisError: axis 2 is out of bounds for array of dimension 2
08-Jun-23 11:00:01 - root - ERROR - Exception occurred
Traceback (most recent call last):
  File "/Users/kaistudio/Desktop/Lotto-generate-website/server/main.py", line 65, in <module>
    rounded_predictions = np.argmax(predictions, axis=2)
                          ^^^^^^^^^^^^^^^^^^^^^^^^^^^^^^
  File "<__array_function__ internals>", line 200, in argmax
  File "/Users/kaistudio/.local/share/virtualenvs/server-vWPLkNok/lib/python3.11/site-packages/numpy/core/fromnumeric.py", line 1242, in argmax
    return _wrapfunc(a, 'argmax', axis=axis, out=out, **kwds)
           ^^^^^^^^^^^^^^^^^^^^^^^^^^^^^^^^^^^^^^^^^^^^^^^^^^
  File "/Users/kaistudio/.local/share/virtualenvs/server-vWPLkNok/lib/python3.11/site-packages/numpy/core/fromnumeric.py", line 57, in _wrapfunc
    return bound(*args, **kwds)
           ^^^^^^^^^^^^^^^^^^^^
numpy.AxisError: axis 2 is out of bounds for array of dimension 2
08-Jun-23 11:00:44 - root - ERROR - Exception occurred
Traceback (most recent call last):
  File "/Users/kaistudio/Desktop/Lotto-generate-website/server/main.py", line 65, in <module>
    rounded_predictions = np.argmax(predictions, axis=2)
                          ^^^^^^^^^^^^^^^^^^^^^^^^^^^^^^
  File "<__array_function__ internals>", line 200, in argmax
  File "/Users/kaistudio/.local/share/virtualenvs/server-vWPLkNok/lib/python3.11/site-packages/numpy/core/fromnumeric.py", line 1242, in argmax
    return _wrapfunc(a, 'argmax', axis=axis, out=out, **kwds)
           ^^^^^^^^^^^^^^^^^^^^^^^^^^^^^^^^^^^^^^^^^^^^^^^^^^
  File "/Users/kaistudio/.local/share/virtualenvs/server-vWPLkNok/lib/python3.11/site-packages/numpy/core/fromnumeric.py", line 57, in _wrapfunc
    return bound(*args, **kwds)
           ^^^^^^^^^^^^^^^^^^^^
numpy.AxisError: axis 2 is out of bounds for array of dimension 2
08-Jun-23 11:01:58 - root - ERROR - Exception occurred
Traceback (most recent call last):
  File "/Users/kaistudio/Desktop/Lotto-generate-website/server/main.py", line 65, in <module>
    rounded_predictions = np.argmax(predictions, axis=2)
                          ^^^^^^^^^^^^^^^^^^^^^^^^^^^^^^
  File "<__array_function__ internals>", line 200, in argmax
  File "/Users/kaistudio/.local/share/virtualenvs/server-vWPLkNok/lib/python3.11/site-packages/numpy/core/fromnumeric.py", line 1242, in argmax
    return _wrapfunc(a, 'argmax', axis=axis, out=out, **kwds)
           ^^^^^^^^^^^^^^^^^^^^^^^^^^^^^^^^^^^^^^^^^^^^^^^^^^
  File "/Users/kaistudio/.local/share/virtualenvs/server-vWPLkNok/lib/python3.11/site-packages/numpy/core/fromnumeric.py", line 57, in _wrapfunc
    return bound(*args, **kwds)
           ^^^^^^^^^^^^^^^^^^^^
numpy.AxisError: axis 2 is out of bounds for array of dimension 2
08-Jun-23 11:02:28 - root - ERROR - Exception occurred
Traceback (most recent call last):
  File "/Users/kaistudio/Desktop/Lotto-generate-website/server/main.py", line 68, in <module>
    print(f"n_steps={n_steps}: {rounded_predictions}")
                                ^^^^^^^^^^^^^^^^^^^
NameError: name 'rounded_predictions' is not defined
08-Jun-23 11:02:45 - root - ERROR - Exception occurred
Traceback (most recent call last):
  File "/Users/kaistudio/Desktop/Lotto-generate-website/server/main.py", line 68, in <module>
    print(f"n_steps={n_steps}: {rounded_predictions}")
                                ^^^^^^^^^^^^^^^^^^^
NameError: name 'rounded_predictions' is not defined
08-Jun-23 11:02:54 - root - ERROR - Exception occurred
Traceback (most recent call last):
  File "/Users/kaistudio/Desktop/Lotto-generate-website/server/main.py", line 68, in <module>
    print(f"n_steps={n_steps}: {rounded_predictions}")
                                ^^^^^^^^^^^^^^^^^^^
NameError: name 'rounded_predictions' is not defined
08-Jun-23 11:04:57 - root - ERROR - Exception occurred
Traceback (most recent call last):
  File "/Users/kaistudio/Desktop/Lotto-generate-website/server/main.py", line 59, in <module>
    print(   x_input = np.array([data[:n_steps]], dtype=np.float32))
TypeError: 'x_input' is an invalid keyword argument for print()
08-Jun-23 11:12:55 - root - ERROR - Exception occurred
Traceback (most recent call last):
  File "/Users/kaistudio/Desktop/Lotto-generate-website/server/main.py", line 62, in <module>
    print(round(predictions))
          ^^^^^^^^^^^^^^^^^^
TypeError: type numpy.ndarray doesn't define __round__ method
08-Jun-23 11:13:33 - root - ERROR - Exception occurred
Traceback (most recent call last):
  File "/Users/kaistudio/Desktop/Lotto-generate-website/server/main.py", line 62, in <module>
    rounded_predictions = round(predictions)
                          ^^^^^^^^^^^^^^^^^^
TypeError: type numpy.ndarray doesn't define __round__ method
08-Jun-23 11:13:47 - root - ERROR - Exception occurred
Traceback (most recent call last):
  File "/Users/kaistudio/Desktop/Lotto-generate-website/server/main.py", line 62, in <module>
    rounded_predictions = round(predictions[0])
                          ^^^^^^^^^^^^^^^^^^^^^
TypeError: type numpy.ndarray doesn't define __round__ method
08-Jun-23 12:01:14 - root - ERROR - Exception occurred
Traceback (most recent call last):
  File "/Users/kaistudio/Desktop/Lotto-generate-website/server/main.py", line 65, in <module>
    predictions.append(rounded_prediction)
    ^^^^^^^^^^^
NameError: name 'predictions' is not defined
16-Jun-23 16:04:12 - root - ERROR - Exception occurred
Traceback (most recent call last):
  File "/Users/kaistudio/.local/share/virtualenvs/server-vWPLkNok/lib/python3.11/site-packages/pandas/core/internals/construction.py", line 934, in _finalize_columns_and_data
    columns = _validate_or_indexify_columns(contents, columns)
              ^^^^^^^^^^^^^^^^^^^^^^^^^^^^^^^^^^^^^^^^^^^^^^^^
  File "/Users/kaistudio/.local/share/virtualenvs/server-vWPLkNok/lib/python3.11/site-packages/pandas/core/internals/construction.py", line 981, in _validate_or_indexify_columns
    raise AssertionError(
AssertionError: 6 columns passed, passed data had 7 columns

The above exception was the direct cause of the following exception:

Traceback (most recent call last):
  File "/Users/kaistudio/Desktop/Lotto-generate-website/server/LSTM_training.py", line 94, in <module>
    preprocessing()
  File "/Users/kaistudio/Desktop/Lotto-generate-website/server/LSTM_training.py", line 54, in preprocessing
    df = pd.DataFrame(data, columns=['1번', '2번', '3번', '4번', '5번', '6번'])
         ^^^^^^^^^^^^^^^^^^^^^^^^^^^^^^^^^^^^^^^^^^^^^^^^^^^^^^^^^^^^^^^^
  File "/Users/kaistudio/.local/share/virtualenvs/server-vWPLkNok/lib/python3.11/site-packages/pandas/core/frame.py", line 782, in __init__
    arrays, columns, index = nested_data_to_arrays(
                             ^^^^^^^^^^^^^^^^^^^^^^
  File "/Users/kaistudio/.local/share/virtualenvs/server-vWPLkNok/lib/python3.11/site-packages/pandas/core/internals/construction.py", line 498, in nested_data_to_arrays
    arrays, columns = to_arrays(data, columns, dtype=dtype)
                      ^^^^^^^^^^^^^^^^^^^^^^^^^^^^^^^^^^^^^
  File "/Users/kaistudio/.local/share/virtualenvs/server-vWPLkNok/lib/python3.11/site-packages/pandas/core/internals/construction.py", line 840, in to_arrays
    content, columns = _finalize_columns_and_data(arr, columns, dtype)
                       ^^^^^^^^^^^^^^^^^^^^^^^^^^^^^^^^^^^^^^^^^^^^^^^
  File "/Users/kaistudio/.local/share/virtualenvs/server-vWPLkNok/lib/python3.11/site-packages/pandas/core/internals/construction.py", line 937, in _finalize_columns_and_data
    raise ValueError(err) from err
ValueError: 6 columns passed, passed data had 7 columns
16-Jun-23 16:04:26 - root - ERROR - Exception occurred
Traceback (most recent call last):
  File "/Users/kaistudio/.local/share/virtualenvs/server-vWPLkNok/lib/python3.11/site-packages/pandas/core/internals/construction.py", line 934, in _finalize_columns_and_data
    columns = _validate_or_indexify_columns(contents, columns)
              ^^^^^^^^^^^^^^^^^^^^^^^^^^^^^^^^^^^^^^^^^^^^^^^^
  File "/Users/kaistudio/.local/share/virtualenvs/server-vWPLkNok/lib/python3.11/site-packages/pandas/core/internals/construction.py", line 981, in _validate_or_indexify_columns
    raise AssertionError(
AssertionError: 6 columns passed, passed data had 7 columns

The above exception was the direct cause of the following exception:

Traceback (most recent call last):
  File "/Users/kaistudio/Desktop/Lotto-generate-website/server/LSTM_training.py", line 94, in <module>
    preprocessing()
  File "/Users/kaistudio/Desktop/Lotto-generate-website/server/LSTM_training.py", line 54, in preprocessing
    df = pd.DataFrame(data, columns=['1번', '2번', '3번', '4번', '5번', '6번'])
         ^^^^^^^^^^^^^^^^^^^^^^^^^^^^^^^^^^^^^^^^^^^^^^^^^^^^^^^^^^^^^^^^
  File "/Users/kaistudio/.local/share/virtualenvs/server-vWPLkNok/lib/python3.11/site-packages/pandas/core/frame.py", line 782, in __init__
    arrays, columns, index = nested_data_to_arrays(
                             ^^^^^^^^^^^^^^^^^^^^^^
  File "/Users/kaistudio/.local/share/virtualenvs/server-vWPLkNok/lib/python3.11/site-packages/pandas/core/internals/construction.py", line 498, in nested_data_to_arrays
    arrays, columns = to_arrays(data, columns, dtype=dtype)
                      ^^^^^^^^^^^^^^^^^^^^^^^^^^^^^^^^^^^^^
  File "/Users/kaistudio/.local/share/virtualenvs/server-vWPLkNok/lib/python3.11/site-packages/pandas/core/internals/construction.py", line 840, in to_arrays
    content, columns = _finalize_columns_and_data(arr, columns, dtype)
                       ^^^^^^^^^^^^^^^^^^^^^^^^^^^^^^^^^^^^^^^^^^^^^^^
  File "/Users/kaistudio/.local/share/virtualenvs/server-vWPLkNok/lib/python3.11/site-packages/pandas/core/internals/construction.py", line 937, in _finalize_columns_and_data
    raise ValueError(err) from err
ValueError: 6 columns passed, passed data had 7 columns
16-Jun-23 16:04:33 - root - ERROR - Exception occurred
Traceback (most recent call last):
  File "/Users/kaistudio/.local/share/virtualenvs/server-vWPLkNok/lib/python3.11/site-packages/pandas/core/internals/construction.py", line 934, in _finalize_columns_and_data
    columns = _validate_or_indexify_columns(contents, columns)
              ^^^^^^^^^^^^^^^^^^^^^^^^^^^^^^^^^^^^^^^^^^^^^^^^
  File "/Users/kaistudio/.local/share/virtualenvs/server-vWPLkNok/lib/python3.11/site-packages/pandas/core/internals/construction.py", line 981, in _validate_or_indexify_columns
    raise AssertionError(
AssertionError: 6 columns passed, passed data had 7 columns

The above exception was the direct cause of the following exception:

Traceback (most recent call last):
  File "/Users/kaistudio/Desktop/Lotto-generate-website/server/LSTM_training.py", line 94, in <module>
    preprocessing()
  File "/Users/kaistudio/Desktop/Lotto-generate-website/server/LSTM_training.py", line 54, in preprocessing
    df = pd.DataFrame(data, columns=['1번', '2번', '3번', '4번', '5번', '6번'])
         ^^^^^^^^^^^^^^^^^^^^^^^^^^^^^^^^^^^^^^^^^^^^^^^^^^^^^^^^^^^^^^^^
  File "/Users/kaistudio/.local/share/virtualenvs/server-vWPLkNok/lib/python3.11/site-packages/pandas/core/frame.py", line 782, in __init__
    arrays, columns, index = nested_data_to_arrays(
                             ^^^^^^^^^^^^^^^^^^^^^^
  File "/Users/kaistudio/.local/share/virtualenvs/server-vWPLkNok/lib/python3.11/site-packages/pandas/core/internals/construction.py", line 498, in nested_data_to_arrays
    arrays, columns = to_arrays(data, columns, dtype=dtype)
                      ^^^^^^^^^^^^^^^^^^^^^^^^^^^^^^^^^^^^^
  File "/Users/kaistudio/.local/share/virtualenvs/server-vWPLkNok/lib/python3.11/site-packages/pandas/core/internals/construction.py", line 840, in to_arrays
    content, columns = _finalize_columns_and_data(arr, columns, dtype)
                       ^^^^^^^^^^^^^^^^^^^^^^^^^^^^^^^^^^^^^^^^^^^^^^^
  File "/Users/kaistudio/.local/share/virtualenvs/server-vWPLkNok/lib/python3.11/site-packages/pandas/core/internals/construction.py", line 937, in _finalize_columns_and_data
    raise ValueError(err) from err
ValueError: 6 columns passed, passed data had 7 columns
16-Jun-23 16:04:45 - root - ERROR - Exception occurred
Traceback (most recent call last):
  File "/Users/kaistudio/.local/share/virtualenvs/server-vWPLkNok/lib/python3.11/site-packages/pandas/core/internals/construction.py", line 934, in _finalize_columns_and_data
    columns = _validate_or_indexify_columns(contents, columns)
              ^^^^^^^^^^^^^^^^^^^^^^^^^^^^^^^^^^^^^^^^^^^^^^^^
  File "/Users/kaistudio/.local/share/virtualenvs/server-vWPLkNok/lib/python3.11/site-packages/pandas/core/internals/construction.py", line 981, in _validate_or_indexify_columns
    raise AssertionError(
AssertionError: 6 columns passed, passed data had 7 columns

The above exception was the direct cause of the following exception:

Traceback (most recent call last):
  File "/Users/kaistudio/Desktop/Lotto-generate-website/server/LSTM_training.py", line 94, in <module>
    preprocessing()
  File "/Users/kaistudio/Desktop/Lotto-generate-website/server/LSTM_training.py", line 54, in preprocessing
    df = pd.DataFrame(data, columns=['1번', '2번', '3번', '4번', '5번', '6번'])
         ^^^^^^^^^^^^^^^^^^^^^^^^^^^^^^^^^^^^^^^^^^^^^^^^^^^^^^^^^^^^^^^^
  File "/Users/kaistudio/.local/share/virtualenvs/server-vWPLkNok/lib/python3.11/site-packages/pandas/core/frame.py", line 782, in __init__
    arrays, columns, index = nested_data_to_arrays(
                             ^^^^^^^^^^^^^^^^^^^^^^
  File "/Users/kaistudio/.local/share/virtualenvs/server-vWPLkNok/lib/python3.11/site-packages/pandas/core/internals/construction.py", line 498, in nested_data_to_arrays
    arrays, columns = to_arrays(data, columns, dtype=dtype)
                      ^^^^^^^^^^^^^^^^^^^^^^^^^^^^^^^^^^^^^
  File "/Users/kaistudio/.local/share/virtualenvs/server-vWPLkNok/lib/python3.11/site-packages/pandas/core/internals/construction.py", line 840, in to_arrays
    content, columns = _finalize_columns_and_data(arr, columns, dtype)
                       ^^^^^^^^^^^^^^^^^^^^^^^^^^^^^^^^^^^^^^^^^^^^^^^
  File "/Users/kaistudio/.local/share/virtualenvs/server-vWPLkNok/lib/python3.11/site-packages/pandas/core/internals/construction.py", line 937, in _finalize_columns_and_data
    raise ValueError(err) from err
ValueError: 6 columns passed, passed data had 7 columns
16-Jun-23 16:04:55 - root - ERROR - Exception occurred
Traceback (most recent call last):
  File "/Users/kaistudio/.local/share/virtualenvs/server-vWPLkNok/lib/python3.11/site-packages/pandas/core/internals/construction.py", line 934, in _finalize_columns_and_data
    columns = _validate_or_indexify_columns(contents, columns)
              ^^^^^^^^^^^^^^^^^^^^^^^^^^^^^^^^^^^^^^^^^^^^^^^^
  File "/Users/kaistudio/.local/share/virtualenvs/server-vWPLkNok/lib/python3.11/site-packages/pandas/core/internals/construction.py", line 981, in _validate_or_indexify_columns
    raise AssertionError(
AssertionError: 6 columns passed, passed data had 7 columns

The above exception was the direct cause of the following exception:

Traceback (most recent call last):
  File "/Users/kaistudio/Desktop/Lotto-generate-website/server/LSTM_training.py", line 94, in <module>
    preprocessing()
  File "/Users/kaistudio/Desktop/Lotto-generate-website/server/LSTM_training.py", line 54, in preprocessing
    df = pd.DataFrame(data, columns=['1번', '2번', '3번', '4번', '5번', '6번'])
         ^^^^^^^^^^^^^^^^^^^^^^^^^^^^^^^^^^^^^^^^^^^^^^^^^^^^^^^^^^^^^^^^
  File "/Users/kaistudio/.local/share/virtualenvs/server-vWPLkNok/lib/python3.11/site-packages/pandas/core/frame.py", line 782, in __init__
    arrays, columns, index = nested_data_to_arrays(
                             ^^^^^^^^^^^^^^^^^^^^^^
  File "/Users/kaistudio/.local/share/virtualenvs/server-vWPLkNok/lib/python3.11/site-packages/pandas/core/internals/construction.py", line 498, in nested_data_to_arrays
    arrays, columns = to_arrays(data, columns, dtype=dtype)
                      ^^^^^^^^^^^^^^^^^^^^^^^^^^^^^^^^^^^^^
  File "/Users/kaistudio/.local/share/virtualenvs/server-vWPLkNok/lib/python3.11/site-packages/pandas/core/internals/construction.py", line 840, in to_arrays
    content, columns = _finalize_columns_and_data(arr, columns, dtype)
                       ^^^^^^^^^^^^^^^^^^^^^^^^^^^^^^^^^^^^^^^^^^^^^^^
  File "/Users/kaistudio/.local/share/virtualenvs/server-vWPLkNok/lib/python3.11/site-packages/pandas/core/internals/construction.py", line 937, in _finalize_columns_and_data
    raise ValueError(err) from err
ValueError: 6 columns passed, passed data had 7 columns
16-Jun-23 16:05:11 - root - ERROR - Exception occurred
Traceback (most recent call last):
  File "/Users/kaistudio/.local/share/virtualenvs/server-vWPLkNok/lib/python3.11/site-packages/pandas/core/internals/construction.py", line 934, in _finalize_columns_and_data
    columns = _validate_or_indexify_columns(contents, columns)
              ^^^^^^^^^^^^^^^^^^^^^^^^^^^^^^^^^^^^^^^^^^^^^^^^
  File "/Users/kaistudio/.local/share/virtualenvs/server-vWPLkNok/lib/python3.11/site-packages/pandas/core/internals/construction.py", line 981, in _validate_or_indexify_columns
    raise AssertionError(
AssertionError: 6 columns passed, passed data had 7 columns

The above exception was the direct cause of the following exception:

Traceback (most recent call last):
  File "/Users/kaistudio/Desktop/Lotto-generate-website/server/LSTM_training.py", line 94, in <module>
    preprocessing()
  File "/Users/kaistudio/Desktop/Lotto-generate-website/server/LSTM_training.py", line 54, in preprocessing
    df = pd.DataFrame(data, columns=['1번', '2번', '3번', '4번', '5번', '6번'])
         ^^^^^^^^^^^^^^^^^^^^^^^^^^^^^^^^^^^^^^^^^^^^^^^^^^^^^^^^^^^^^^^^
  File "/Users/kaistudio/.local/share/virtualenvs/server-vWPLkNok/lib/python3.11/site-packages/pandas/core/frame.py", line 782, in __init__
    arrays, columns, index = nested_data_to_arrays(
                             ^^^^^^^^^^^^^^^^^^^^^^
  File "/Users/kaistudio/.local/share/virtualenvs/server-vWPLkNok/lib/python3.11/site-packages/pandas/core/internals/construction.py", line 498, in nested_data_to_arrays
    arrays, columns = to_arrays(data, columns, dtype=dtype)
                      ^^^^^^^^^^^^^^^^^^^^^^^^^^^^^^^^^^^^^
  File "/Users/kaistudio/.local/share/virtualenvs/server-vWPLkNok/lib/python3.11/site-packages/pandas/core/internals/construction.py", line 840, in to_arrays
    content, columns = _finalize_columns_and_data(arr, columns, dtype)
                       ^^^^^^^^^^^^^^^^^^^^^^^^^^^^^^^^^^^^^^^^^^^^^^^
  File "/Users/kaistudio/.local/share/virtualenvs/server-vWPLkNok/lib/python3.11/site-packages/pandas/core/internals/construction.py", line 937, in _finalize_columns_and_data
    raise ValueError(err) from err
ValueError: 6 columns passed, passed data had 7 columns
16-Jun-23 16:06:17 - root - ERROR - Exception occurred
Traceback (most recent call last):
  File "/Users/kaistudio/.local/share/virtualenvs/server-vWPLkNok/lib/python3.11/site-packages/pandas/core/internals/construction.py", line 934, in _finalize_columns_and_data
    columns = _validate_or_indexify_columns(contents, columns)
              ^^^^^^^^^^^^^^^^^^^^^^^^^^^^^^^^^^^^^^^^^^^^^^^^
  File "/Users/kaistudio/.local/share/virtualenvs/server-vWPLkNok/lib/python3.11/site-packages/pandas/core/internals/construction.py", line 981, in _validate_or_indexify_columns
    raise AssertionError(
AssertionError: 6 columns passed, passed data had 7 columns

The above exception was the direct cause of the following exception:

Traceback (most recent call last):
  File "/Users/kaistudio/Desktop/Lotto-generate-website/server/LSTM_training.py", line 94, in <module>
    preprocessing()
  File "/Users/kaistudio/Desktop/Lotto-generate-website/server/LSTM_training.py", line 54, in preprocessing
    df = pd.DataFrame(data, columns=['1번', '2번', '3번', '4번', '5번', '6번'])
         ^^^^^^^^^^^^^^^^^^^^^^^^^^^^^^^^^^^^^^^^^^^^^^^^^^^^^^^^^^^^^^^^
  File "/Users/kaistudio/.local/share/virtualenvs/server-vWPLkNok/lib/python3.11/site-packages/pandas/core/frame.py", line 782, in __init__
    arrays, columns, index = nested_data_to_arrays(
                             ^^^^^^^^^^^^^^^^^^^^^^
  File "/Users/kaistudio/.local/share/virtualenvs/server-vWPLkNok/lib/python3.11/site-packages/pandas/core/internals/construction.py", line 498, in nested_data_to_arrays
    arrays, columns = to_arrays(data, columns, dtype=dtype)
                      ^^^^^^^^^^^^^^^^^^^^^^^^^^^^^^^^^^^^^
  File "/Users/kaistudio/.local/share/virtualenvs/server-vWPLkNok/lib/python3.11/site-packages/pandas/core/internals/construction.py", line 840, in to_arrays
    content, columns = _finalize_columns_and_data(arr, columns, dtype)
                       ^^^^^^^^^^^^^^^^^^^^^^^^^^^^^^^^^^^^^^^^^^^^^^^
  File "/Users/kaistudio/.local/share/virtualenvs/server-vWPLkNok/lib/python3.11/site-packages/pandas/core/internals/construction.py", line 937, in _finalize_columns_and_data
    raise ValueError(err) from err
ValueError: 6 columns passed, passed data had 7 columns
16-Jun-23 16:08:53 - root - ERROR - Exception occurred
Traceback (most recent call last):
  File "/Users/kaistudio/Desktop/Lotto-generate-website/server/main.py", line 64, in generateLotto
    x_input = x_input.reshape((1, n_steps, 7))
              ^^^^^^^^^^^^^^^^^^^^^^^^^^^^^^^^
ValueError: cannot reshape array of size 30 into shape (1,5,7)
16-Jun-23 16:08:56 - root - ERROR - Exception occurred
Traceback (most recent call last):
  File "/Users/kaistudio/Desktop/Lotto-generate-website/server/main.py", line 64, in generateLotto
    x_input = x_input.reshape((1, n_steps, 7))
              ^^^^^^^^^^^^^^^^^^^^^^^^^^^^^^^^
ValueError: cannot reshape array of size 30 into shape (1,5,7)
