18-Aug-23 10:59:56 - root - ERROR - Exception occurred
Traceback (most recent call last):
  File "/Users/kaistudio/Desktop/lotto-generate-website/server/pension/pension_LSTM_training.py", line 80, in generate_pension
    x_input = x_input.reshape((1, n_steps, 7))
              ^^^^^^^^^^^^^^^^^^^^^^^^^^^^^^^^
ValueError: cannot reshape array of size 0 into shape (1,5,7)
18-Aug-23 11:12:57 - tensorflow - WARNING - 5 out of the last 5 calls to <function Model.make_predict_function.<locals>.predict_function at 0x29fc500e0> triggered tf.function retracing. Tracing is expensive and the excessive number of tracings could be due to (1) creating @tf.function repeatedly in a loop, (2) passing tensors with different shapes, (3) passing Python objects instead of tensors. For (1), please define your @tf.function outside of the loop. For (2), @tf.function has reduce_retracing=True option that can avoid unnecessary retracing. For (3), please refer to https://www.tensorflow.org/guide/function#controlling_retracing and https://www.tensorflow.org/api_docs/python/tf/function for  more details.
18-Aug-23 11:13:02 - tensorflow - WARNING - 6 out of the last 6 calls to <function Model.make_predict_function.<locals>.predict_function at 0x2cb5ce160> triggered tf.function retracing. Tracing is expensive and the excessive number of tracings could be due to (1) creating @tf.function repeatedly in a loop, (2) passing tensors with different shapes, (3) passing Python objects instead of tensors. For (1), please define your @tf.function outside of the loop. For (2), @tf.function has reduce_retracing=True option that can avoid unnecessary retracing. For (3), please refer to https://www.tensorflow.org/guide/function#controlling_retracing and https://www.tensorflow.org/api_docs/python/tf/function for  more details.
18-Aug-23 11:16:15 - root - ERROR - Exception occurred
Traceback (most recent call last):
  File "/Users/kaistudio/Desktop/lotto-generate-website/server/pension/pension_LSTM_training.py", line 85, in generate_pension
    prediction = model.predict(x_input)
                 ^^^^^^^^^^^^^^^^^^^^^^
  File "/Users/kaistudio/.local/share/virtualenvs/server-vWPLkNok/lib/python3.11/site-packages/keras/src/utils/traceback_utils.py", line 70, in error_handler
    raise e.with_traceback(filtered_tb) from None
  File "/var/folders/ld/gfz18mn13js_pwjrwct7mndh0000gn/T/__autograph_generated_file_r6lis15.py", line 18, in tf__predict_function
    raise
ValueError: in user code:

    File "/Users/kaistudio/.local/share/virtualenvs/server-vWPLkNok/lib/python3.11/site-packages/keras/src/engine/training.py", line 2341, in predict_function  *
        return step_function(self, iterator)
    File "/Users/kaistudio/.local/share/virtualenvs/server-vWPLkNok/lib/python3.11/site-packages/keras/src/engine/training.py", line 2327, in step_function  **
        outputs = model.distribute_strategy.run(run_step, args=(data,))
    File "/Users/kaistudio/.local/share/virtualenvs/server-vWPLkNok/lib/python3.11/site-packages/keras/src/engine/training.py", line 2315, in run_step  **
        outputs = model.predict_step(data)
    File "/Users/kaistudio/.local/share/virtualenvs/server-vWPLkNok/lib/python3.11/site-packages/keras/src/engine/training.py", line 2283, in predict_step
        return self(x, training=False)
    File "/Users/kaistudio/.local/share/virtualenvs/server-vWPLkNok/lib/python3.11/site-packages/keras/src/utils/traceback_utils.py", line 70, in error_handler
        raise e.with_traceback(filtered_tb) from None
    File "/Users/kaistudio/.local/share/virtualenvs/server-vWPLkNok/lib/python3.11/site-packages/keras/src/engine/input_spec.py", line 298, in assert_input_compatibility
        raise ValueError(

    ValueError: Input 0 of layer "sequential" is incompatible with the layer: expected shape=(None, 5, 7), found shape=(None, 20, 7)

18-Aug-23 11:16:35 - root - ERROR - Exception occurred
Traceback (most recent call last):
  File "/Users/kaistudio/Desktop/lotto-generate-website/server/pension/pension_LSTM_training.py", line 85, in generate_pension
    prediction = model.predict(x_input)
                 ^^^^^^^^^^^^^^^^^^^^^^
  File "/Users/kaistudio/.local/share/virtualenvs/server-vWPLkNok/lib/python3.11/site-packages/keras/src/utils/traceback_utils.py", line 70, in error_handler
    raise e.with_traceback(filtered_tb) from None
  File "/var/folders/ld/gfz18mn13js_pwjrwct7mndh0000gn/T/__autograph_generated_filel8r6vnjw.py", line 18, in tf__predict_function
    raise
ValueError: in user code:

    File "/Users/kaistudio/.local/share/virtualenvs/server-vWPLkNok/lib/python3.11/site-packages/keras/src/engine/training.py", line 2341, in predict_function  *
        return step_function(self, iterator)
    File "/Users/kaistudio/.local/share/virtualenvs/server-vWPLkNok/lib/python3.11/site-packages/keras/src/engine/training.py", line 2327, in step_function  **
        outputs = model.distribute_strategy.run(run_step, args=(data,))
    File "/Users/kaistudio/.local/share/virtualenvs/server-vWPLkNok/lib/python3.11/site-packages/keras/src/engine/training.py", line 2315, in run_step  **
        outputs = model.predict_step(data)
    File "/Users/kaistudio/.local/share/virtualenvs/server-vWPLkNok/lib/python3.11/site-packages/keras/src/engine/training.py", line 2283, in predict_step
        return self(x, training=False)
    File "/Users/kaistudio/.local/share/virtualenvs/server-vWPLkNok/lib/python3.11/site-packages/keras/src/utils/traceback_utils.py", line 70, in error_handler
        raise e.with_traceback(filtered_tb) from None
    File "/Users/kaistudio/.local/share/virtualenvs/server-vWPLkNok/lib/python3.11/site-packages/keras/src/engine/input_spec.py", line 298, in assert_input_compatibility
        raise ValueError(

    ValueError: Input 0 of layer "sequential" is incompatible with the layer: expected shape=(None, 5, 7), found shape=(None, 20, 7)

18-Aug-23 12:32:17 - root - ERROR - Exception occurred
Traceback (most recent call last):
  File "/Users/kaistudio/Desktop/lotto-generate-website/server/lotto/lotto_LSTM_training.py", line 90, in generate_lotto
    prediction = model.predict(x_input)
                 ^^^^^^^^^^^^^^^^^^^^^^
  File "/Users/kaistudio/.local/share/virtualenvs/server-vWPLkNok/lib/python3.11/site-packages/keras/src/utils/traceback_utils.py", line 70, in error_handler
    raise e.with_traceback(filtered_tb) from None
  File "/var/folders/ld/gfz18mn13js_pwjrwct7mndh0000gn/T/__autograph_generated_filen_7q3nzy.py", line 18, in tf__predict_function
    raise
ValueError: in user code:

    File "/Users/kaistudio/.local/share/virtualenvs/server-vWPLkNok/lib/python3.11/site-packages/keras/src/engine/training.py", line 2341, in predict_function  *
        return step_function(self, iterator)
    File "/Users/kaistudio/.local/share/virtualenvs/server-vWPLkNok/lib/python3.11/site-packages/keras/src/engine/training.py", line 2327, in step_function  **
        outputs = model.distribute_strategy.run(run_step, args=(data,))
    File "/Users/kaistudio/.local/share/virtualenvs/server-vWPLkNok/lib/python3.11/site-packages/keras/src/engine/training.py", line 2315, in run_step  **
        outputs = model.predict_step(data)
    File "/Users/kaistudio/.local/share/virtualenvs/server-vWPLkNok/lib/python3.11/site-packages/keras/src/engine/training.py", line 2283, in predict_step
        return self(x, training=False)
    File "/Users/kaistudio/.local/share/virtualenvs/server-vWPLkNok/lib/python3.11/site-packages/keras/src/utils/traceback_utils.py", line 70, in error_handler
        raise e.with_traceback(filtered_tb) from None
    File "/Users/kaistudio/.local/share/virtualenvs/server-vWPLkNok/lib/python3.11/site-packages/keras/src/engine/input_spec.py", line 298, in assert_input_compatibility
        raise ValueError(

    ValueError: Input 0 of layer "sequential_6" is incompatible with the layer: expected shape=(None, 5, 7), found shape=(None, 5, 6)

18-Aug-23 13:48:12 - root - ERROR - Exception occurred
Traceback (most recent call last):
  File "/Users/kaistudio/Desktop/lotto-generate-website/server/lotto/lotto_LSTM_training.py", line 90, in generate_lotto
    prediction = model.predict(x_input)
                 ^^^^^^^^^^^^^^^^^^^^^^
  File "/Users/kaistudio/.local/share/virtualenvs/server-vWPLkNok/lib/python3.11/site-packages/keras/src/utils/traceback_utils.py", line 70, in error_handler
    raise e.with_traceback(filtered_tb) from None
  File "/var/folders/ld/gfz18mn13js_pwjrwct7mndh0000gn/T/__autograph_generated_filen_7q3nzy.py", line 18, in tf__predict_function
    raise
ValueError: in user code:

    File "/Users/kaistudio/.local/share/virtualenvs/server-vWPLkNok/lib/python3.11/site-packages/keras/src/engine/training.py", line 2341, in predict_function  *
        return step_function(self, iterator)
    File "/Users/kaistudio/.local/share/virtualenvs/server-vWPLkNok/lib/python3.11/site-packages/keras/src/engine/training.py", line 2327, in step_function  **
        outputs = model.distribute_strategy.run(run_step, args=(data,))
    File "/Users/kaistudio/.local/share/virtualenvs/server-vWPLkNok/lib/python3.11/site-packages/keras/src/engine/training.py", line 2315, in run_step  **
        outputs = model.predict_step(data)
    File "/Users/kaistudio/.local/share/virtualenvs/server-vWPLkNok/lib/python3.11/site-packages/keras/src/engine/training.py", line 2283, in predict_step
        return self(x, training=False)
    File "/Users/kaistudio/.local/share/virtualenvs/server-vWPLkNok/lib/python3.11/site-packages/keras/src/utils/traceback_utils.py", line 70, in error_handler
        raise e.with_traceback(filtered_tb) from None
    File "/Users/kaistudio/.local/share/virtualenvs/server-vWPLkNok/lib/python3.11/site-packages/keras/src/engine/input_spec.py", line 298, in assert_input_compatibility
        raise ValueError(

    ValueError: Input 0 of layer "sequential_8" is incompatible with the layer: expected shape=(None, 5, 7), found shape=(None, 5, 6)

18-Aug-23 13:57:21 - root - ERROR - Exception occurred
Traceback (most recent call last):
  File "/Users/kaistudio/Desktop/lotto-generate-website/server/lotto/lotto_LSTM_training.py", line 90, in generate_lotto
    prediction = model.predict(x_input)
                 ^^^^^^^^^^^^^^^^^^^^^^
  File "/Users/kaistudio/.local/share/virtualenvs/server-vWPLkNok/lib/python3.11/site-packages/keras/src/utils/traceback_utils.py", line 70, in error_handler
    raise e.with_traceback(filtered_tb) from None
  File "/var/folders/ld/gfz18mn13js_pwjrwct7mndh0000gn/T/__autograph_generated_file6gcbue2n.py", line 18, in tf__predict_function
    raise
ValueError: in user code:

    File "/Users/kaistudio/.local/share/virtualenvs/server-vWPLkNok/lib/python3.11/site-packages/keras/src/engine/training.py", line 2341, in predict_function  *
        return step_function(self, iterator)
    File "/Users/kaistudio/.local/share/virtualenvs/server-vWPLkNok/lib/python3.11/site-packages/keras/src/engine/training.py", line 2327, in step_function  **
        outputs = model.distribute_strategy.run(run_step, args=(data,))
    File "/Users/kaistudio/.local/share/virtualenvs/server-vWPLkNok/lib/python3.11/site-packages/keras/src/engine/training.py", line 2315, in run_step  **
        outputs = model.predict_step(data)
    File "/Users/kaistudio/.local/share/virtualenvs/server-vWPLkNok/lib/python3.11/site-packages/keras/src/engine/training.py", line 2283, in predict_step
        return self(x, training=False)
    File "/Users/kaistudio/.local/share/virtualenvs/server-vWPLkNok/lib/python3.11/site-packages/keras/src/utils/traceback_utils.py", line 70, in error_handler
        raise e.with_traceback(filtered_tb) from None
    File "/Users/kaistudio/.local/share/virtualenvs/server-vWPLkNok/lib/python3.11/site-packages/keras/src/engine/input_spec.py", line 298, in assert_input_compatibility
        raise ValueError(

    ValueError: Input 0 of layer "sequential" is incompatible with the layer: expected shape=(None, 5, 7), found shape=(None, 5, 6)

18-Aug-23 13:57:52 - root - ERROR - Exception occurred
Traceback (most recent call last):
  File "/Users/kaistudio/Desktop/lotto-generate-website/server/lotto/lotto_LSTM_training.py", line 90, in generate_lotto
    prediction = model.predict(x_input)
                 ^^^^^^^^^^^^^^^^^^^^^^
  File "/Users/kaistudio/.local/share/virtualenvs/server-vWPLkNok/lib/python3.11/site-packages/keras/src/utils/traceback_utils.py", line 70, in error_handler
    raise e.with_traceback(filtered_tb) from None
  File "/var/folders/ld/gfz18mn13js_pwjrwct7mndh0000gn/T/__autograph_generated_fileivkqljaq.py", line 18, in tf__predict_function
    raise
ValueError: in user code:

    File "/Users/kaistudio/.local/share/virtualenvs/server-vWPLkNok/lib/python3.11/site-packages/keras/src/engine/training.py", line 2341, in predict_function  *
        return step_function(self, iterator)
    File "/Users/kaistudio/.local/share/virtualenvs/server-vWPLkNok/lib/python3.11/site-packages/keras/src/engine/training.py", line 2327, in step_function  **
        outputs = model.distribute_strategy.run(run_step, args=(data,))
    File "/Users/kaistudio/.local/share/virtualenvs/server-vWPLkNok/lib/python3.11/site-packages/keras/src/engine/training.py", line 2315, in run_step  **
        outputs = model.predict_step(data)
    File "/Users/kaistudio/.local/share/virtualenvs/server-vWPLkNok/lib/python3.11/site-packages/keras/src/engine/training.py", line 2283, in predict_step
        return self(x, training=False)
    File "/Users/kaistudio/.local/share/virtualenvs/server-vWPLkNok/lib/python3.11/site-packages/keras/src/utils/traceback_utils.py", line 70, in error_handler
        raise e.with_traceback(filtered_tb) from None
    File "/Users/kaistudio/.local/share/virtualenvs/server-vWPLkNok/lib/python3.11/site-packages/keras/src/engine/input_spec.py", line 298, in assert_input_compatibility
        raise ValueError(

    ValueError: Input 0 of layer "sequential" is incompatible with the layer: expected shape=(None, 5, 7), found shape=(None, 5, 6)

18-Aug-23 13:59:28 - root - ERROR - Exception occurred
Traceback (most recent call last):
  File "/Users/kaistudio/Desktop/lotto-generate-website/server/lotto/lotto_LSTM_training.py", line 90, in generate_lotto
    prediction = model.predict(x_input)
                 ^^^^^^^^^^^^^^^^^^^^^^
  File "/Users/kaistudio/.local/share/virtualenvs/server-vWPLkNok/lib/python3.11/site-packages/keras/src/utils/traceback_utils.py", line 70, in error_handler
    raise e.with_traceback(filtered_tb) from None
  File "/var/folders/ld/gfz18mn13js_pwjrwct7mndh0000gn/T/__autograph_generated_filept42qpbn.py", line 18, in tf__predict_function
    raise
ValueError: in user code:

    File "/Users/kaistudio/.local/share/virtualenvs/server-vWPLkNok/lib/python3.11/site-packages/keras/src/engine/training.py", line 2341, in predict_function  *
        return step_function(self, iterator)
    File "/Users/kaistudio/.local/share/virtualenvs/server-vWPLkNok/lib/python3.11/site-packages/keras/src/engine/training.py", line 2327, in step_function  **
        outputs = model.distribute_strategy.run(run_step, args=(data,))
    File "/Users/kaistudio/.local/share/virtualenvs/server-vWPLkNok/lib/python3.11/site-packages/keras/src/engine/training.py", line 2315, in run_step  **
        outputs = model.predict_step(data)
    File "/Users/kaistudio/.local/share/virtualenvs/server-vWPLkNok/lib/python3.11/site-packages/keras/src/engine/training.py", line 2283, in predict_step
        return self(x, training=False)
    File "/Users/kaistudio/.local/share/virtualenvs/server-vWPLkNok/lib/python3.11/site-packages/keras/src/utils/traceback_utils.py", line 70, in error_handler
        raise e.with_traceback(filtered_tb) from None
    File "/Users/kaistudio/.local/share/virtualenvs/server-vWPLkNok/lib/python3.11/site-packages/keras/src/engine/input_spec.py", line 298, in assert_input_compatibility
        raise ValueError(

    ValueError: Input 0 of layer "sequential" is incompatible with the layer: expected shape=(None, 5, 7), found shape=(None, 5, 6)

21-Aug-23 11:02:12 - root - ERROR - Exception occurred
Traceback (most recent call last):
  File "/Users/kaistudio/Desktop/lotto-generate-website/server/pension/pension.py", line 120, in get_round_number_all_pension
    circuit_numbers = [cell.text.strip() for cell in cells[-19]] #회차 번호
                                                     ~~~~~^^^^^
IndexError: list index out of range
21-Aug-23 11:02:41 - root - ERROR - Exception occurred
Traceback (most recent call last):
  File "/Users/kaistudio/Desktop/lotto-generate-website/server/pension/pension.py", line 120, in get_round_number_all_pension
    circuit_numbers = [cell.text.strip() for cell in cells[-19]] #회차 번호
                                                     ~~~~~^^^^^
IndexError: list index out of range
21-Aug-23 11:03:48 - root - ERROR - Exception occurred
Traceback (most recent call last):
  File "/Users/kaistudio/Desktop/lotto-generate-website/server/pension/pension.py", line 120, in get_round_number_all_pension
    circuit_numbers = [cell.text.strip() for cell in cells[-19]] #회차 번호
                                                     ~~~~~^^^^^
IndexError: list index out of range
21-Aug-23 11:04:19 - root - ERROR - Exception occurred
Traceback (most recent call last):
  File "/Users/kaistudio/Desktop/lotto-generate-website/server/pension/pension.py", line 120, in get_round_number_all_pension
    circuit_numbers = [cell.text.strip() for cell in cells[-19]] #회차 번호
                                                     ~~~~~^^^^^
IndexError: list index out of range
21-Aug-23 11:05:09 - root - ERROR - Exception occurred
Traceback (most recent call last):
  File "/Users/kaistudio/Desktop/lotto-generate-website/server/pension/pension.py", line 120, in get_round_number_all_pension
    circuit_numbers = [cell.text.strip() for cell in cells[-15]] #회차 번호
                                                     ~~~~~^^^^^
IndexError: list index out of range
21-Aug-23 11:47:33 - root - ERROR - Exception occurred
Traceback (most recent call last):
  File "/Users/kaistudio/Desktop/lotto-generate-website/server/pension/pension.py", line 111, in get_round_number_pension
    winning_numbers = format_numbers(winning_numbers)
                      ^^^^^^^^^^^^^^^^^^^^^^^^^^^^^^^
  File "/Users/kaistudio/Desktop/lotto-generate-website/server/pension/pension.py", line 84, in format_numbers
    number = number.replace("조", "")
             ^^^^^^^^^^^^^^
AttributeError: 'list' object has no attribute 'replace'
21-Aug-23 11:48:54 - root - ERROR - Exception occurred
Traceback (most recent call last):
  File "/Users/kaistudio/Desktop/lotto-generate-website/server/pension/pension.py", line 111, in get_round_number_pension
    winning_numbers = format_numbers(winning_numbers)
                      ^^^^^^^^^^^^^^^^^^^^^^^^^^^^^^^
  File "/Users/kaistudio/Desktop/lotto-generate-website/server/pension/pension.py", line 84, in format_numbers
    number = number.replace("조", "")
             ^^^^^^^^^^^^^^
AttributeError: 'list' object has no attribute 'replace'
21-Aug-23 11:50:11 - root - ERROR - Exception occurred
Traceback (most recent call last):
  File "/Users/kaistudio/Desktop/lotto-generate-website/server/pension/pension.py", line 113, in get_round_number_pension
    bonus_number = format_numbers(bonus_number)
                   ^^^^^^^^^^^^^^^^^^^^^^^^^^^^
  File "/Users/kaistudio/Desktop/lotto-generate-website/server/pension/pension.py", line 84, in format_numbers
    number = number.replace("조", "")
             ^^^^^^^^^^^^^^
AttributeError: 'list' object has no attribute 'replace'
